<?xml version="1.0" encoding="UTF-8"?>
<!-- Generated by org.testng.reporters.JUnitReportReporter -->
<testsuite hostname="DESKTOP-R6U7DT6" name="com.hxy.mail.test" tests="6" failures="4" timestamp="25 Nov 2020 01:28:28 GMT" time="0.009" errors="0">
  <testcase name="test6" time="0.000" classname="com.hxy.mail.test"/>
  <testcase name="test3" time="0.000" classname="com.hxy.mail.test">
    <failure type="java.lang.AssertionError" message="expected [2] but found [4]">
      <![CDATA[java.lang.AssertionError: expected [2] but found [4]
	at org.testng.Assert.fail(Assert.java:94)
	at org.testng.Assert.failNotEquals(Assert.java:496)
	at org.testng.Assert.assertEquals(Assert.java:125)
	at org.testng.Assert.assertEquals(Assert.java:178)
	at org.testng.Assert.assertEquals(Assert.java:188)
	at com.hxy.mail.test.test3(test.java:22)
	at sun.reflect.NativeMethodAccessorImpl.invoke0(Native Method)
	at sun.reflect.NativeMethodAccessorImpl.invoke(Unknown Source)
	at sun.reflect.DelegatingMethodAccessorImpl.invoke(Unknown Source)
	at java.lang.reflect.Method.invoke(Unknown Source)
	at org.testng.internal.MethodInvocationHelper.invokeMethod(MethodInvocationHelper.java:85)
	at org.testng.internal.Invoker.invokeMethod(Invoker.java:639)
	at org.testng.internal.Invoker.invokeTestMethod(Invoker.java:816)
	at org.testng.internal.Invoker.invokeTestMethods(Invoker.java:1124)
	at org.testng.internal.TestMethodWorker.invokeTestMethods(TestMethodWorker.java:125)
	at org.testng.internal.TestMethodWorker.run(TestMethodWorker.java:108)
	at org.testng.TestRunner.privateRun(TestRunner.java:774)
	at org.testng.TestRunner.run(TestRunner.java:624)
	at org.testng.SuiteRunner.runTest(SuiteRunner.java:359)
	at org.testng.SuiteRunner.runSequentially(SuiteRunner.java:354)
	at org.testng.SuiteRunner.privateRun(SuiteRunner.java:312)
	at org.testng.SuiteRunner.run(SuiteRunner.java:261)
	at org.testng.SuiteRunnerWorker.runSuite(SuiteRunnerWorker.java:52)
	at org.testng.SuiteRunnerWorker.run(SuiteRunnerWorker.java:86)
	at org.testng.TestNG.runSuitesSequentially(TestNG.java:1191)
	at org.testng.TestNG.runSuitesLocally(TestNG.java:1116)
	at org.testng.TestNG.run(TestNG.java:1024)
	at org.testng.remote.RemoteTestNG.run(RemoteTestNG.java:112)
	at org.testng.remote.RemoteTestNG.initAndRun(RemoteTestNG.java:205)
	at org.testng.remote.RemoteTestNG.main(RemoteTestNG.java:176)
]]>
    </failure>
  </testcase> <!-- test3 -->
  <testcase name="test1" time="0.007" classname="com.hxy.mail.test">
    <failure type="java.lang.AssertionError" message="expected [2] but found [1]">
      <![CDATA[java.lang.AssertionError: expected [2] but found [1]
	at org.testng.Assert.fail(Assert.java:94)
	at org.testng.Assert.failNotEquals(Assert.java:496)
	at org.testng.Assert.assertEquals(Assert.java:125)
	at org.testng.Assert.assertEquals(Assert.java:178)
	at org.testng.Assert.assertEquals(Assert.java:188)
	at com.hxy.mail.test.test1(test.java:14)
	at sun.reflect.NativeMethodAccessorImpl.invoke0(Native Method)
	at sun.reflect.NativeMethodAccessorImpl.invoke(Unknown Source)
	at sun.reflect.DelegatingMethodAccessorImpl.invoke(Unknown Source)
	at java.lang.reflect.Method.invoke(Unknown Source)
	at org.testng.internal.MethodInvocationHelper.invokeMethod(MethodInvocationHelper.java:85)
	at org.testng.internal.Invoker.invokeMethod(Invoker.java:639)
	at org.testng.internal.Invoker.invokeTestMethod(Invoker.java:816)
	at org.testng.internal.Invoker.invokeTestMethods(Invoker.java:1124)
	at org.testng.internal.TestMethodWorker.invokeTestMethods(TestMethodWorker.java:125)
	at org.testng.internal.TestMethodWorker.run(TestMethodWorker.java:108)
	at org.testng.TestRunner.privateRun(TestRunner.java:774)
	at org.testng.TestRunner.run(TestRunner.java:624)
	at org.testng.SuiteRunner.runTest(SuiteRunner.java:359)
	at org.testng.SuiteRunner.runSequentially(SuiteRunner.java:354)
	at org.testng.SuiteRunner.privateRun(SuiteRunner.java:312)
	at org.testng.SuiteRunner.run(SuiteRunner.java:261)
	at org.testng.SuiteRunnerWorker.runSuite(SuiteRunnerWorker.java:52)
	at org.testng.SuiteRunnerWorker.run(SuiteRunnerWorker.java:86)
	at org.testng.TestNG.runSuitesSequentially(TestNG.java:1191)
	at org.testng.TestNG.runSuitesLocally(TestNG.java:1116)
	at org.testng.TestNG.run(TestNG.java:1024)
	at org.testng.remote.RemoteTestNG.run(RemoteTestNG.java:112)
	at org.testng.remote.RemoteTestNG.initAndRun(RemoteTestNG.java:205)
	at org.testng.remote.RemoteTestNG.main(RemoteTestNG.java:176)
]]>
    </failure>
  </testcase> <!-- test1 -->
  <testcase name="test2" time="0.001" classname="com.hxy.mail.test"/>
  <testcase name="test5" time="0.000" classname="com.hxy.mail.test">
    <failure type="java.lang.AssertionError" message="expected [2] but found [6]">
      <![CDATA[java.lang.AssertionError: expected [2] but found [6]
	at org.testng.Assert.fail(Assert.java:94)
	at org.testng.Assert.failNotEquals(Assert.java:496)
	at org.testng.Assert.assertEquals(Assert.java:125)
	at org.testng.Assert.assertEquals(Assert.java:178)
	at org.testng.Assert.assertEquals(Assert.java:188)
	at com.hxy.mail.test.test5(test.java:30)
	at sun.reflect.NativeMethodAccessorImpl.invoke0(Native Method)
	at sun.reflect.NativeMethodAccessorImpl.invoke(Unknown Source)
	at sun.reflect.DelegatingMethodAccessorImpl.invoke(Unknown Source)
	at java.lang.reflect.Method.invoke(Unknown Source)
	at org.testng.internal.MethodInvocationHelper.invokeMethod(MethodInvocationHelper.java:85)
	at org.testng.internal.Invoker.invokeMethod(Invoker.java:639)
	at org.testng.internal.Invoker.invokeTestMethod(Invoker.java:816)
	at org.testng.internal.Invoker.invokeTestMethods(Invoker.java:1124)
	at org.testng.internal.TestMethodWorker.invokeTestMethods(TestMethodWorker.java:125)
	at org.testng.internal.TestMethodWorker.run(TestMethodWorker.java:108)
	at org.testng.TestRunner.privateRun(TestRunner.java:774)
	at org.testng.TestRunner.run(TestRunner.java:624)
	at org.testng.SuiteRunner.runTest(SuiteRunner.java:359)
	at org.testng.SuiteRunner.runSequentially(SuiteRunner.java:354)
	at org.testng.SuiteRunner.privateRun(SuiteRunner.java:312)
	at org.testng.SuiteRunner.run(SuiteRunner.java:261)
	at org.testng.SuiteRunnerWorker.runSuite(SuiteRunnerWorker.java:52)
	at org.testng.SuiteRunnerWorker.run(SuiteRunnerWorker.java:86)
	at org.testng.TestNG.runSuitesSequentially(TestNG.java:1191)
	at org.testng.TestNG.runSuitesLocally(TestNG.java:1116)
	at org.testng.TestNG.run(TestNG.java:1024)
	at org.testng.remote.RemoteTestNG.run(RemoteTestNG.java:112)
	at org.testng.remote.RemoteTestNG.initAndRun(RemoteTestNG.java:205)
	at org.testng.remote.RemoteTestNG.main(RemoteTestNG.java:176)
]]>
    </failure>
  </testcase> <!-- test5 -->
  <testcase name="test4" time="0.001" classname="com.hxy.mail.test">
    <failure type="java.lang.AssertionError" message="expected [2] but found [9]">
      <![CDATA[java.lang.AssertionError: expected [2] but found [9]
	at org.testng.Assert.fail(Assert.java:94)
	at org.testng.Assert.failNotEquals(Assert.java:496)
	at org.testng.Assert.assertEquals(Assert.java:125)
	at org.testng.Assert.assertEquals(Assert.java:178)
	at org.testng.Assert.assertEquals(Assert.java:188)
	at com.hxy.mail.test.test4(test.java:26)
	at sun.reflect.NativeMethodAccessorImpl.invoke0(Native Method)
	at sun.reflect.NativeMethodAccessorImpl.invoke(Unknown Source)
	at sun.reflect.DelegatingMethodAccessorImpl.invoke(Unknown Source)
	at java.lang.reflect.Method.invoke(Unknown Source)
	at org.testng.internal.MethodInvocationHelper.invokeMethod(MethodInvocationHelper.java:85)
	at org.testng.internal.Invoker.invokeMethod(Invoker.java:639)
	at org.testng.internal.Invoker.invokeTestMethod(Invoker.java:816)
	at org.testng.internal.Invoker.invokeTestMethods(Invoker.java:1124)
	at org.testng.internal.TestMethodWorker.invokeTestMethods(TestMethodWorker.java:125)
	at org.testng.internal.TestMethodWorker.run(TestMethodWorker.java:108)
	at org.testng.TestRunner.privateRun(TestRunner.java:774)
	at org.testng.TestRunner.run(TestRunner.java:624)
	at org.testng.SuiteRunner.runTest(SuiteRunner.java:359)
	at org.testng.SuiteRunner.runSequentially(SuiteRunner.java:354)
	at org.testng.SuiteRunner.privateRun(SuiteRunner.java:312)
	at org.testng.SuiteRunner.run(SuiteRunner.java:261)
	at org.testng.SuiteRunnerWorker.runSuite(SuiteRunnerWorker.java:52)
	at org.testng.SuiteRunnerWorker.run(SuiteRunnerWorker.java:86)
	at org.testng.TestNG.runSuitesSequentially(TestNG.java:1191)
	at org.testng.TestNG.runSuitesLocally(TestNG.java:1116)
	at org.testng.TestNG.run(TestNG.java:1024)
	at org.testng.remote.RemoteTestNG.run(RemoteTestNG.java:112)
	at org.testng.remote.RemoteTestNG.initAndRun(RemoteTestNG.java:205)
	at org.testng.remote.RemoteTestNG.main(RemoteTestNG.java:176)
]]>
    </failure>
  </testcase> <!-- test4 -->
</testsuite> <!-- com.hxy.mail.test -->
